[2024-10-02T12:42:46.367+0000] {taskinstance.py:1157} INFO - Dependencies all met for dep_context=non-requeueable deps ti=<TaskInstance: test_pipeline.test_task manual__2024-10-02T12:42:45.164001+00:00 [queued]>
[2024-10-02T12:42:46.380+0000] {taskinstance.py:1157} INFO - Dependencies all met for dep_context=requeueable deps ti=<TaskInstance: test_pipeline.test_task manual__2024-10-02T12:42:45.164001+00:00 [queued]>
[2024-10-02T12:42:46.381+0000] {taskinstance.py:1359} INFO - Starting attempt 1 of 1
[2024-10-02T12:42:46.398+0000] {taskinstance.py:1380} INFO - Executing <Task(PythonOperator): test_task> on 2024-10-02 12:42:45.164001+00:00
[2024-10-02T12:42:46.404+0000] {standard_task_runner.py:57} INFO - Started process 142 to run task
[2024-10-02T12:42:46.408+0000] {standard_task_runner.py:84} INFO - Running: ['***', 'tasks', 'run', 'test_pipeline', 'test_task', 'manual__2024-10-02T12:42:45.164001+00:00', '--job-id', '24', '--raw', '--subdir', 'DAGS_FOLDER/published_data_dag.py', '--cfg-path', '/tmp/tmpj4xj4qhy']
[2024-10-02T12:42:46.411+0000] {standard_task_runner.py:85} INFO - Job 24: Subtask test_task
[2024-10-02T12:42:46.498+0000] {task_command.py:415} INFO - Running <TaskInstance: test_pipeline.test_task manual__2024-10-02T12:42:45.164001+00:00 [running]> on host addf1b8c90fb
[2024-10-02T12:42:46.651+0000] {taskinstance.py:1660} INFO - Exporting env vars: AIRFLOW_CTX_DAG_OWNER='Biokpor Solomon' AIRFLOW_CTX_DAG_ID='test_pipeline' AIRFLOW_CTX_TASK_ID='test_task' AIRFLOW_CTX_EXECUTION_DATE='2024-10-02T12:42:45.164001+00:00' AIRFLOW_CTX_TRY_NUMBER='1' AIRFLOW_CTX_DAG_RUN_ID='manual__2024-10-02T12:42:45.164001+00:00'
[2024-10-02T12:42:46.916+0000] {taskinstance.py:1935} ERROR - Task failed with exception
Traceback (most recent call last):
  File "/home/airflow/.local/lib/python3.9/site-packages/airflow/operators/python.py", line 192, in execute
    return_value = self.execute_callable()
  File "/home/airflow/.local/lib/python3.9/site-packages/airflow/operators/python.py", line 209, in execute_callable
    return self.python_callable(*self.op_args, **self.op_kwargs)
  File "/opt/airflow/dags/published_data_dag.py", line 18, in download_using_xpath
    extracted_data = tree.xpath(xpath)
UnboundLocalError: local variable 'xpath' referenced before assignment
[2024-10-02T12:42:46.937+0000] {taskinstance.py:1398} INFO - Marking task as FAILED. dag_id=test_pipeline, task_id=test_task, execution_date=20241002T124245, start_date=20241002T124246, end_date=20241002T124246
[2024-10-02T12:42:46.953+0000] {standard_task_runner.py:104} ERROR - Failed to execute job 24 for task test_task (local variable 'xpath' referenced before assignment; 142)
[2024-10-02T12:42:46.986+0000] {local_task_job_runner.py:228} INFO - Task exited with return code 1
[2024-10-02T12:42:47.014+0000] {taskinstance.py:2776} INFO - 0 downstream tasks scheduled from follow-on schedule check
