[2024-09-27T10:19:09.794+0000] {taskinstance.py:1157} INFO - Dependencies all met for dep_context=non-requeueable deps ti=<TaskInstance: etl_jd_pipeline.jdsport_pandas manual__2024-09-27T10:19:00.617828+00:00 [queued]>
[2024-09-27T10:19:09.807+0000] {taskinstance.py:1157} INFO - Dependencies all met for dep_context=requeueable deps ti=<TaskInstance: etl_jd_pipeline.jdsport_pandas manual__2024-09-27T10:19:00.617828+00:00 [queued]>
[2024-09-27T10:19:09.807+0000] {taskinstance.py:1359} INFO - Starting attempt 1 of 1
[2024-09-27T10:19:09.827+0000] {taskinstance.py:1380} INFO - Executing <Task(PythonOperator): jdsport_pandas> on 2024-09-27 10:19:00.617828+00:00
[2024-09-27T10:19:09.841+0000] {standard_task_runner.py:57} INFO - Started process 51 to run task
[2024-09-27T10:19:09.841+0000] {standard_task_runner.py:84} INFO - Running: ['***', 'tasks', 'run', 'etl_jd_pipeline', 'jdsport_pandas', 'manual__2024-09-27T10:19:00.617828+00:00', '--job-id', '3', '--raw', '--subdir', 'DAGS_FOLDER/jdsports_dag.py', '--cfg-path', '/tmp/tmpvepkddrj']
[2024-09-27T10:19:09.847+0000] {standard_task_runner.py:85} INFO - Job 3: Subtask jdsport_pandas
[2024-09-27T10:19:09.938+0000] {task_command.py:415} INFO - Running <TaskInstance: etl_jd_pipeline.jdsport_pandas manual__2024-09-27T10:19:00.617828+00:00 [running]> on host 304a62aaae75
[2024-09-27T10:19:10.397+0000] {taskinstance.py:1660} INFO - Exporting env vars: AIRFLOW_CTX_DAG_OWNER='Biokpor Solomon' AIRFLOW_CTX_DAG_ID='etl_jd_pipeline' AIRFLOW_CTX_TASK_ID='jdsport_pandas' AIRFLOW_CTX_EXECUTION_DATE='2024-09-27T10:19:00.617828+00:00' AIRFLOW_CTX_TRY_NUMBER='1' AIRFLOW_CTX_DAG_RUN_ID='manual__2024-09-27T10:19:00.617828+00:00'
[2024-09-27T10:19:10.400+0000] {taskinstance.py:1935} ERROR - Task failed with exception
Traceback (most recent call last):
  File "/home/airflow/.local/lib/python3.9/site-packages/airflow/operators/python.py", line 192, in execute
    return_value = self.execute_callable()
  File "/home/airflow/.local/lib/python3.9/site-packages/airflow/operators/python.py", line 209, in execute_callable
    return self.python_callable(*self.op_args, **self.op_kwargs)
  File "/opt/airflow/pipelines/jdsports_pipeline.py", line 4, in jdsports_pipeline
    use_pandas()
  File "/opt/airflow/etls/jdsports_etl.py", line 5, in use_pandas
    df = pd.read_json('/opt/airflow/fastfashion/jdsport.json')
  File "/home/airflow/.local/lib/python3.9/site-packages/pandas/io/json/_json.py", line 780, in read_json
    json_reader = JsonReader(
  File "/home/airflow/.local/lib/python3.9/site-packages/pandas/io/json/_json.py", line 893, in __init__
    data = self._get_data_from_filepath(filepath_or_buffer)
  File "/home/airflow/.local/lib/python3.9/site-packages/pandas/io/json/_json.py", line 949, in _get_data_from_filepath
    raise FileNotFoundError(f"File {filepath_or_buffer} does not exist")
FileNotFoundError: File /opt/***/fastfashion/jdsport.json does not exist
[2024-09-27T10:19:10.421+0000] {taskinstance.py:1398} INFO - Marking task as FAILED. dag_id=etl_jd_pipeline, task_id=jdsport_pandas, execution_date=20240927T101900, start_date=20240927T101909, end_date=20240927T101910
[2024-09-27T10:19:10.435+0000] {standard_task_runner.py:104} ERROR - Failed to execute job 3 for task jdsport_pandas (File /opt/***/fastfashion/jdsport.json does not exist; 51)
[2024-09-27T10:19:10.467+0000] {local_task_job_runner.py:228} INFO - Task exited with return code 1
[2024-09-27T10:19:10.520+0000] {taskinstance.py:2776} INFO - 0 downstream tasks scheduled from follow-on schedule check
