[2024-09-27T14:22:02.712+0000] {taskinstance.py:1157} INFO - Dependencies all met for dep_context=non-requeueable deps ti=<TaskInstance: etl_jd_pipeline.jdsport_pandas manual__2024-09-27T14:18:34.841869+00:00 [queued]>
[2024-09-27T14:22:02.724+0000] {taskinstance.py:1157} INFO - Dependencies all met for dep_context=requeueable deps ti=<TaskInstance: etl_jd_pipeline.jdsport_pandas manual__2024-09-27T14:18:34.841869+00:00 [queued]>
[2024-09-27T14:22:02.724+0000] {taskinstance.py:1359} INFO - Starting attempt 2 of 2
[2024-09-27T14:22:02.738+0000] {taskinstance.py:1380} INFO - Executing <Task(PythonOperator): jdsport_pandas> on 2024-09-27 14:18:34.841869+00:00
[2024-09-27T14:22:02.753+0000] {standard_task_runner.py:57} INFO - Started process 112 to run task
[2024-09-27T14:22:02.764+0000] {standard_task_runner.py:84} INFO - Running: ['***', 'tasks', 'run', 'etl_jd_pipeline', 'jdsport_pandas', 'manual__2024-09-27T14:18:34.841869+00:00', '--job-id', '17', '--raw', '--subdir', 'DAGS_FOLDER/jdsports_dag.py', '--cfg-path', '/tmp/tmpem20svjh']
[2024-09-27T14:22:02.768+0000] {standard_task_runner.py:85} INFO - Job 17: Subtask jdsport_pandas
[2024-09-27T14:22:02.870+0000] {task_command.py:415} INFO - Running <TaskInstance: etl_jd_pipeline.jdsport_pandas manual__2024-09-27T14:18:34.841869+00:00 [running]> on host e8e1afcccdee
[2024-09-27T14:22:03.085+0000] {taskinstance.py:1660} INFO - Exporting env vars: AIRFLOW_CTX_DAG_OWNER='Biokpor Solomon' AIRFLOW_CTX_DAG_ID='etl_jd_pipeline' AIRFLOW_CTX_TASK_ID='jdsport_pandas' AIRFLOW_CTX_EXECUTION_DATE='2024-09-27T14:18:34.841869+00:00' AIRFLOW_CTX_TRY_NUMBER='2' AIRFLOW_CTX_DAG_RUN_ID='manual__2024-09-27T14:18:34.841869+00:00'
[2024-09-27T14:22:03.089+0000] {taskinstance.py:1935} ERROR - Task failed with exception
Traceback (most recent call last):
  File "/home/airflow/.local/lib/python3.9/site-packages/airflow/operators/python.py", line 192, in execute
    return_value = self.execute_callable()
  File "/home/airflow/.local/lib/python3.9/site-packages/airflow/operators/python.py", line 209, in execute_callable
    return self.python_callable(*self.op_args, **self.op_kwargs)
  File "/opt/airflow/pipelines/jdsports_pipeline.py", line 6, in jdsports_pipeline
    df = use_pandas('/opt/airflow/fastfashion/jdsportraw.csv')
  File "/opt/airflow/etls/jdsports_etl.py", line 7, in use_pandas
    df = pd.read_csv(file)
  File "/home/airflow/.local/lib/python3.9/site-packages/pandas/io/parsers/readers.py", line 948, in read_csv
    return _read(filepath_or_buffer, kwds)
  File "/home/airflow/.local/lib/python3.9/site-packages/pandas/io/parsers/readers.py", line 611, in _read
    parser = TextFileReader(filepath_or_buffer, **kwds)
  File "/home/airflow/.local/lib/python3.9/site-packages/pandas/io/parsers/readers.py", line 1448, in __init__
    self._engine = self._make_engine(f, self.engine)
  File "/home/airflow/.local/lib/python3.9/site-packages/pandas/io/parsers/readers.py", line 1705, in _make_engine
    self.handles = get_handle(
  File "/home/airflow/.local/lib/python3.9/site-packages/pandas/io/common.py", line 863, in get_handle
    handle = open(
FileNotFoundError: [Errno 2] No such file or directory: '/opt/airflow/fastfashion/jdsportraw.csv'
[2024-09-27T14:22:03.111+0000] {taskinstance.py:1398} INFO - Marking task as FAILED. dag_id=etl_jd_pipeline, task_id=jdsport_pandas, execution_date=20240927T141834, start_date=20240927T142202, end_date=20240927T142203
[2024-09-27T14:22:03.127+0000] {standard_task_runner.py:104} ERROR - Failed to execute job 17 for task jdsport_pandas ([Errno 2] No such file or directory: '/opt/airflow/fastfashion/jdsportraw.csv'; 112)
[2024-09-27T14:22:03.176+0000] {local_task_job_runner.py:228} INFO - Task exited with return code 1
[2024-09-27T14:22:03.226+0000] {taskinstance.py:2776} INFO - 0 downstream tasks scheduled from follow-on schedule check
