[2024-10-02T12:35:57.174+0000] {taskinstance.py:1157} INFO - Dependencies all met for dep_context=non-requeueable deps ti=<TaskInstance: test_pipeline.test_task manual__2024-10-02T12:35:56.050135+00:00 [queued]>
[2024-10-02T12:35:57.187+0000] {taskinstance.py:1157} INFO - Dependencies all met for dep_context=requeueable deps ti=<TaskInstance: test_pipeline.test_task manual__2024-10-02T12:35:56.050135+00:00 [queued]>
[2024-10-02T12:35:57.187+0000] {taskinstance.py:1359} INFO - Starting attempt 1 of 1
[2024-10-02T12:35:57.212+0000] {taskinstance.py:1380} INFO - Executing <Task(PythonOperator): test_task> on 2024-10-02 12:35:56.050135+00:00
[2024-10-02T12:35:57.220+0000] {standard_task_runner.py:57} INFO - Started process 134 to run task
[2024-10-02T12:35:57.226+0000] {standard_task_runner.py:84} INFO - Running: ['***', 'tasks', 'run', 'test_pipeline', 'test_task', 'manual__2024-10-02T12:35:56.050135+00:00', '--job-id', '20', '--raw', '--subdir', 'DAGS_FOLDER/published_data_dag.py', '--cfg-path', '/tmp/tmpqojli1u5']
[2024-10-02T12:35:57.231+0000] {standard_task_runner.py:85} INFO - Job 20: Subtask test_task
[2024-10-02T12:35:57.334+0000] {task_command.py:415} INFO - Running <TaskInstance: test_pipeline.test_task manual__2024-10-02T12:35:56.050135+00:00 [running]> on host addf1b8c90fb
[2024-10-02T12:35:57.497+0000] {taskinstance.py:1660} INFO - Exporting env vars: AIRFLOW_CTX_DAG_OWNER='Biokpor Solomon' AIRFLOW_CTX_DAG_ID='test_pipeline' AIRFLOW_CTX_TASK_ID='test_task' AIRFLOW_CTX_EXECUTION_DATE='2024-10-02T12:35:56.050135+00:00' AIRFLOW_CTX_TRY_NUMBER='1' AIRFLOW_CTX_DAG_RUN_ID='manual__2024-10-02T12:35:56.050135+00:00'
[2024-10-02T12:35:57.499+0000] {taskinstance.py:1935} ERROR - Task failed with exception
Traceback (most recent call last):
  File "/home/airflow/.local/lib/python3.9/site-packages/airflow/operators/python.py", line 192, in execute
    return_value = self.execute_callable()
  File "/home/airflow/.local/lib/python3.9/site-packages/airflow/operators/python.py", line 209, in execute_callable
    return self.python_callable(*self.op_args, **self.op_kwargs)
  File "/opt/airflow/dags/published_data_dag.py", line 15, in download_using_xpath
    response = requests.get(url)
UnboundLocalError: local variable 'url' referenced before assignment
[2024-10-02T12:35:57.519+0000] {taskinstance.py:1398} INFO - Marking task as FAILED. dag_id=test_pipeline, task_id=test_task, execution_date=20241002T123556, start_date=20241002T123557, end_date=20241002T123557
[2024-10-02T12:35:57.533+0000] {standard_task_runner.py:104} ERROR - Failed to execute job 20 for task test_task (local variable 'url' referenced before assignment; 134)
[2024-10-02T12:35:57.561+0000] {local_task_job_runner.py:228} INFO - Task exited with return code 1
[2024-10-02T12:35:57.596+0000] {taskinstance.py:2776} INFO - 0 downstream tasks scheduled from follow-on schedule check
